<?xml version='1.0'?>
<sdf version='1.7'>
  <model name='limo_four_diff'>
    <link name='base_footprint'>
      <inertial>
        <pose>0.007905 0 0.160821 0 -0 0</pose>
        <mass>2.3657</mass>
        <inertia>
          <ixx>0.248941</ixx>
          <ixy>0</ixy>
          <ixz>-0.00196744</ixz>
          <iyy>0.970559</iyy>
          <iyz>0</iyz>
          <izz>0.961621</izz>
        </inertia>
      </inertial>
      <collision name='base_footprint_fixed_joint_lump__base_link_collision'>
        <pose>0 0 0.15 0 -0 0</pose>
        <geometry>
          <box>
            <size>0.13 0.12 0.1</size>
          </box>
        </geometry>
      </collision>
      <collision name='base_footprint_fixed_joint_lump__depth_camera_collision_collision_1'>
        <pose>0.084 0 0.015 0 -0 0</pose>
        <geometry>
          <box>
            <size>0.02 0.06 0.015</size>
          </box>
        </geometry>
      </collision>
      <collision name='base_footprint_fixed_joint_lump__imu_collision_collision_2'>
        <pose>0 0 0.05 0 -0 0</pose>
        <geometry>
          <box>
            <size>0.001 0.001 0.001</size>
          </box>
        </geometry>
      </collision>
      <collision name='base_footprint_fixed_joint_lump__laser_collision_collision_3'>
        <pose>0.103 0 0.116 0 -0 0</pose>
        <geometry>
          <cylinder>
            <length>0.016</length>
            <radius>0.032</radius>
          </cylinder>
        </geometry>
      </collision>
      <visual name='base_footprint_fixed_joint_lump__base_link_visual'>
        <pose>0 0 0 0 -0 1.57</pose>
        <geometry>
          <mesh>
            <scale>1 1 1</scale>
            <uri>model://limo_four_diff/meshes/limo_base.dae</uri>
          </mesh>
        </geometry>
      </visual>
      <visual name='base_footprint_fixed_joint_lump__depth_camera_visual_visual_1'>
        <pose>0.084 0 0.015 0 -0 0</pose>
        <geometry>
          <box>
            <size>0.02 0.06 0.015</size>
          </box>
        </geometry>
      </visual>
      <visual name='base_footprint_fixed_joint_lump__imu_visual_visual_2'>
        <pose>0 0 0.05 0 -0 0</pose>
        <geometry>
          <box>
            <size>0.001 0.001 0.001</size>
          </box>
        </geometry>
      </visual>
      <visual name='base_footprint_fixed_joint_lump__laser_visual_visual_3'>
        <pose>0.103 0 0.116 0 -0 0</pose>
        <geometry>
          <cylinder>
            <length>0.01</length>
            <radius>0.02</radius>
          </cylinder>
        </geometry>
      </visual>
      <sensor name='sensor_camera' type='depth'>
        <always_on>1</always_on>
        <visualize>1</visualize>
        <update_rate>30</update_rate>
        <camera name='limo_camera'>
          <horizontal_fov>1.047</horizontal_fov>
          <image>
            <width>320</width>
            <height>240</height>
          </image>
          <clip>
            <near>0.05</near>
            <far>3.5</far>
          </clip>
        </camera>
        <plugin name='gazebo_ros_depth_camera_sensor' filename='libgazebo_ros_camera.so'>
          <ros>
            <namespace>/limo</namespace>
            <argument>limo_camera/image_raw:=limo_camera/image</argument>
            <argument>limo_camera/image_depth:=limo_camera/depth/camera_image_depth</argument>
            <argument>limo_camera/camera_info:=limo_camera/camera_info_raw</argument>
            <argument>limo_camera/camera_info_depth:=limo_camera/camera_info_depth</argument>
            <argument>limo_camera/points:=limo_camera/camera_points</argument>
          </ros>
          <camera_name>depth_camera_link</camera_name>
          <frame_name>base_footprint</frame_name>
          <hack_baseline>0.07</hack_baseline>
          <min_depth>0.001</min_depth>
        </plugin>
        <pose>0.084 0 0.45 0 -0 0</pose>
      </sensor>
      <gravity>1</gravity>
      <sensor name='twr_imu' type='imu'>
        <always_on>1</always_on>
        <update_rate>100</update_rate>
        <visualize>1</visualize>
        <imu>
          <angular_velocity>
            <x>
              <noise type='gaussian'>
                <mean>0</mean>
                <stddev>0.0002</stddev>
              </noise>
            </x>
            <y>
              <noise type='gaussian'>
                <mean>0</mean>
                <stddev>0.0002</stddev>
              </noise>
            </y>
            <z>
              <noise type='gaussian'>
                <mean>0</mean>
                <stddev>0.0002</stddev>
              </noise>
            </z>
          </angular_velocity>
          <linear_acceleration>
            <x>
              <noise type='gaussian'>
                <mean>0</mean>
                <stddev>0.017</stddev>
              </noise>
            </x>
            <y>
              <noise type='gaussian'>
                <mean>0</mean>
                <stddev>0.017</stddev>
              </noise>
            </y>
            <z>
              <noise type='gaussian'>
                <mean>0</mean>
                <stddev>0.017</stddev>
              </noise>
            </z>
          </linear_acceleration>
          <orientation>
            <x>
              <noise type='gaussian'>
                <mean>0.0</mean>
                <stddev>2e-3</stddev>
              </noise>
            </x>
            <y>
              <noise type='gaussian'>
                <mean>0.0</mean>
                <stddev>2e-3</stddev>
              </noise>
            </y>
            <z>
              <noise type='gaussian'>
                <mean>0.0</mean>
                <stddev>2e-3</stddev>
              </noise>
            </z>
          </orientation>
        </imu>
        <plugin name='two_wheeled_robot_imu' filename='libgazebo_ros_imu_sensor.so'>
          <initial_orientation_as_reference>0</initial_orientation_as_reference>
          <frame_name>base_footprint</frame_name>
          <ros>
            <namespace>/imu</namespace>
            <remapping>~/out:=data</remapping>
          </ros>
        </plugin>
        <pose>0 0 0.05 0 -0 0</pose>
      </sensor>
      <sensor name='laser' type='ray'>
        <always_on>1</always_on>
        <visualize>1</visualize>
        <update_rate>10</update_rate>
        <ray>
          <scan>
            <horizontal>
              <samples>120</samples>
              <resolution>1</resolution>
              <min_angle>-3.14159</min_angle>
              <max_angle>3.14159</max_angle>
            </horizontal>
          </scan>
          <range>
            <min>0.3</min>
            <max>15</max>
            <resolution>0.015</resolution>
          </range>
          <noise>
            <type>gaussian</type>
            <mean>0</mean>
            <stddev>0.01</stddev>
          </noise>
        </ray>
        <plugin name='scan' filename='libgazebo_ros_ray_sensor.so'>
          <ros>
            <remapping>~/out:=scan</remapping>
          </ros>
          <output_type>sensor_msgs/LaserScan</output_type>
          <frame_name>base_footprint</frame_name>
        </plugin>
        <pose>0.103 0 0.116 0 -0 0</pose>
      </sensor>
    </link>
    <joint name='front_left_wheel' type='revolute'>
      <pose relative_to='base_footprint'>0.1 0.065 0.05 0 -0 0</pose>
      <parent>base_footprint</parent>
      <child>front_left_wheel_link</child>
      <axis>
        <xyz>0 1 0</xyz>
        <limit>
          <lower>-1e+16</lower>
          <upper>1e+16</upper>
        </limit>
        <dynamics>
          <spring_reference>0</spring_reference>
          <spring_stiffness>0</spring_stiffness>
        </dynamics>
      </axis>
      <physics>
        <ode>
          <limit>
            <cfm>0</cfm>
            <erp>0.2</erp>
          </limit>
        </ode>
      </physics>
    </joint>
    <link name='front_left_wheel_link'>
      <pose relative_to='front_left_wheel'>0 0 0 0 -0 0</pose>
      <inertial>
        <pose>0 0 0 0 -0 0</pose>
        <mass>0.5</mass>
        <inertia>
          <ixx>0.01055</ixx>
          <ixy>0</ixy>
          <ixz>0</ixz>
          <iyy>0.00075</iyy>
          <iyz>0</iyz>
          <izz>0.01055</izz>
        </inertia>
      </inertial>
      <collision name='front_left_wheel_link_collision'>
        <pose>0 0.0225 0 1.57 -0 0</pose>
        <geometry>
          <cylinder>
            <length>0.045</length>
            <radius>0.045</radius>
          </cylinder>
        </geometry>
      </collision>
      <visual name='front_left_wheel_link_visual'>
        <pose>0 0 0 0 -0 0</pose>
        <geometry>
          <mesh>
            <scale>1 1 1</scale>
            <uri>model://limo_four_diff/meshes/limo_wheel.dae</uri>
          </mesh>
        </geometry>
      </visual>
    </link>
    <joint name='front_right_wheel' type='revolute'>
      <pose relative_to='base_footprint'>0.1 -0.065 0.05 3.14159 -0 0</pose>
      <parent>base_footprint</parent>
      <child>front_right_wheel_link</child>
      <axis>
        <xyz>0 -1 0</xyz>
        <limit>
          <lower>-1e+16</lower>
          <upper>1e+16</upper>
        </limit>
        <dynamics>
          <spring_reference>0</spring_reference>
          <spring_stiffness>0</spring_stiffness>
        </dynamics>
      </axis>
      <physics>
        <ode>
          <limit>
            <cfm>0</cfm>
            <erp>0.2</erp>
          </limit>
        </ode>
      </physics>
    </joint>
    <link name='front_right_wheel_link'>
      <pose relative_to='front_right_wheel'>0 0 0 0 -0 0</pose>
      <inertial>
        <pose>0 0 0 0 -0 0</pose>
        <mass>0.5</mass>
        <inertia>
          <ixx>0.01055</ixx>
          <ixy>0</ixy>
          <ixz>0</ixz>
          <iyy>0.00075</iyy>
          <iyz>0</iyz>
          <izz>0.01055</izz>
        </inertia>
      </inertial>
      <collision name='front_right_wheel_link_collision'>
        <pose>0 0.0225 0 1.57 -0 0</pose>
        <geometry>
          <cylinder>
            <length>0.045</length>
            <radius>0.045</radius>
          </cylinder>
        </geometry>
      </collision>
      <visual name='front_right_wheel_link_visual'>
        <pose>0 0 0 0 -0 0</pose>
        <geometry>
          <mesh>
            <scale>1 1 1</scale>
            <uri>model://limo_four_diff/meshes/limo_wheel.dae</uri>
          </mesh>
        </geometry>
      </visual>
    </link>
    <joint name='rear_left_wheel' type='revolute'>
      <pose relative_to='base_footprint'>-0.1 0.065 0.05 0 -0 0</pose>
      <parent>base_footprint</parent>
      <child>rear_left_wheel_link</child>
      <axis>
        <xyz>0 1 0</xyz>
        <limit>
          <lower>-1e+16</lower>
          <upper>1e+16</upper>
        </limit>
        <dynamics>
          <spring_reference>0</spring_reference>
          <spring_stiffness>0</spring_stiffness>
        </dynamics>
      </axis>
      <physics>
        <ode>
          <limit>
            <cfm>0</cfm>
            <erp>0.2</erp>
          </limit>
        </ode>
      </physics>
    </joint>
    <link name='rear_left_wheel_link'>
      <pose relative_to='rear_left_wheel'>0 0 0 0 -0 0</pose>
      <inertial>
        <pose>0 0 0 0 -0 0</pose>
        <mass>0.5</mass>
        <inertia>
          <ixx>0.01055</ixx>
          <ixy>0</ixy>
          <ixz>0</ixz>
          <iyy>0.00075</iyy>
          <iyz>0</iyz>
          <izz>0.01055</izz>
        </inertia>
      </inertial>
      <collision name='rear_left_wheel_link_collision'>
        <pose>0 0.0225 0 1.57 -0 0</pose>
        <geometry>
          <cylinder>
            <length>0.045</length>
            <radius>0.045</radius>
          </cylinder>
        </geometry>
      </collision>
      <visual name='rear_left_wheel_link_visual'>
        <pose>0 0 0 0 -0 0</pose>
        <geometry>
          <mesh>
            <scale>1 1 1</scale>
            <uri>model://limo_four_diff/meshes/limo_wheel.dae</uri>
          </mesh>
        </geometry>
      </visual>
    </link>
    <joint name='rear_right_wheel' type='revolute'>
      <pose relative_to='base_footprint'>-0.1 -0.065 0.05 3.14159 -0 0</pose>
      <parent>base_footprint</parent>
      <child>rear_right_wheel_link</child>
      <axis>
        <xyz>0 -1 0</xyz>
        <limit>
          <lower>-1e+16</lower>
          <upper>1e+16</upper>
        </limit>
        <dynamics>
          <spring_reference>0</spring_reference>
          <spring_stiffness>0</spring_stiffness>
        </dynamics>
      </axis>
      <physics>
        <ode>
          <limit>
            <cfm>0</cfm>
            <erp>0.2</erp>
          </limit>
        </ode>
      </physics>
    </joint>
    <link name='rear_right_wheel_link'>
      <pose relative_to='rear_right_wheel'>0 0 0 0 -0 0</pose>
      <inertial>
        <pose>0 0 0 0 -0 0</pose>
        <mass>0.5</mass>
        <inertia>
          <ixx>0.01055</ixx>
          <ixy>0</ixy>
          <ixz>0</ixz>
          <iyy>0.00075</iyy>
          <iyz>0</iyz>
          <izz>0.01055</izz>
        </inertia>
      </inertial>
      <collision name='rear_right_wheel_link_collision'>
        <pose>0 0.0225 0 1.57 -0 0</pose>
        <geometry>
          <cylinder>
            <length>0.045</length>
            <radius>0.045</radius>
          </cylinder>
        </geometry>
      </collision>
      <visual name='rear_right_wheel_link_visual'>
        <pose>0 0 0 0 -0 0</pose>
        <geometry>
          <mesh>
            <scale>1 1 1</scale>
            <uri>model://limo_four_diff/meshes/limo_wheel.dae</uri>
          </mesh>
        </geometry>
      </visual>
    </link>
    <static>0</static>
    <plugin name='four_diff_controller' filename='libgazebo_ros_diff_drive.so'>
      <update_rate>50</update_rate>
      <num_wheel_pairs>2</num_wheel_pairs>
      <left_joint>front_left_wheel</left_joint>
      <right_joint>front_right_wheel</right_joint>
      <left_joint>rear_left_wheel</left_joint>
      <right_joint>rear_right_wheel</right_joint>
      <wheel_separation>0.172</wheel_separation>
      <wheel_diameter>0.09</wheel_diameter>
      <max_wheel_torque>20</max_wheel_torque>
      <max_wheel_acceleration>1.0</max_wheel_acceleration>
      <command_topic>cmd_vel</command_topic>
      <publish_odom>1</publish_odom>
      <publish_odom_tf>1</publish_odom_tf>
      <publish_wheel_tf>1</publish_wheel_tf>
      <odometry_topic>odom</odometry_topic>
      <odometry_frame>odom</odometry_frame>
      <robot_base_frame>base_footprint</robot_base_frame>
      <odometry_source>1</odometry_source>
      <ros>
        <remapping>odom:=/odometry</remapping>
      </ros>
    </plugin>
  </model>
</sdf>
